<sdf version='1.5'>
  <model name='ker'>
    <link name='odom'>
      <pose frame=''>0 0 0 0 -0 0</pose>
      <inertial>
        <pose frame=''>0 0 0 0 -0 0</pose>
        <mass>0.104525</mass>
        <inertia>
          <ixx>7.935e-05</ixx>
          <ixy>-3.8e-07</ixy>
          <ixz>1.27e-06</ixz>
          <iyy>0.00016719</iyy>
          <iyz>3e-08</iyz>
          <izz>0.00023972</izz>
        </inertia>
      </inertial>
      <velocity_decay>
        <linear>10000000</linear>
        <angular>10000000</angular>
      </velocity_decay>
      <collision name='odom_collision'>
        <pose frame=''>0 0 0 0 -0 0</pose>
        <geometry>
          <box>
            <size>0 0 0</size>
          </box>
        </geometry>
      </collision>
      <collision name='odom_collision_odom_1'>
        <pose frame=''>0 0 0 0 -0 0</pose>
        <geometry>
          <box>
            <size>0.2 0.12 0.031</size>
          </box>
        </geometry>
      </collision>
      <visual name='odom_visual'>
        <pose frame=''>0 0 0 0 -0 0</pose>
        <geometry>
          <box>
            <size>0 0 0</size>
          </box>
        </geometry>
      </visual>
      <visual name='odom_visual_odom_1'>
        <pose frame=''>0 0 0 0 -0 0</pose>
        <geometry>
          <mesh>
            <scale>1 1 1</scale>
            <uri>model://ker_description/meshes/platf_3_1.STL</uri>
          </mesh>
        </geometry>
      </visual>
    </link>
    <link name='motor_1'>
      <pose frame=''>0.073 0.036 0.0005 0 -0 0</pose>
      <inertial>
        <pose frame=''>0 0 -0.0125 0 -0 0</pose>
        <mass>0.0082825</mass>
        <inertia>
          <ixx>1.63e-06</ixx>
          <ixy>0</ixy>
          <ixz>0</ixz>
          <iyy>1.14e-06</iyy>
          <iyz>0</iyz>
          <izz>1.03e-06</izz>
        </inertia>
      </inertial>
      <collision name='motor_1_collision'>
        <pose frame=''>0 0 -0.0125 0 -0 0</pose>
        <geometry>
          <box>
            <size>0.022 0.0344 0.0472</size>
          </box>
        </geometry>
      </collision>
      <visual name='motor_1_visual'>
        <pose frame=''>0 0 -0.0125 0 -0 0</pose>
        <geometry>
          <mesh>
            <scale>1 1 1</scale>
            <uri>model://ker_description/meshes/roll.STL</uri>
          </mesh>
        </geometry>
      </visual>
    </link>
    <joint name='motor_1_joint' type='revolute'>
      <child>motor_1</child>
      <parent>odom</parent>
      <axis>
        <xyz>1 0 0</xyz>
        <limit>
          <lower>-3.14</lower>
          <upper>3.14</upper>
          <effort>10</effort>
          <velocity>0.5</velocity>
        </limit>
        <dynamics>
          <damping>0</damping>
          <friction>0</friction>
          <spring_reference>0</spring_reference>
          <spring_stiffness>0</spring_stiffness>
        </dynamics>
        <use_parent_model_frame>1</use_parent_model_frame>
      </axis>
    </joint>
    <link name='humerus_1'>
      <pose frame=''>0.073 0.036 -0.0267 0 -0 0</pose>
      <inertial>
        <pose frame=''>0 0 -0.028 0 -0 0</pose>
        <mass>0.0361976</mass>
        <inertia>
          <ixx>2.198e-05</ixx>
          <ixy>0</ixy>
          <ixz>4e-08</ixz>
          <iyy>2.188e-05</iyy>
          <iyz>0</iyz>
          <izz>3.91e-06</izz>
        </inertia>
      </inertial>
      <velocity_decay>
        <linear>10000000</linear>
        <angular>10000000</angular>
      </velocity_decay>
      <collision name='humerus_1_collision'>
        <pose frame=''>0 0 -0.028 0 -0 0</pose>
        <geometry>
          <box>
            <size>0.022 0.025 0.076</size>
          </box>
        </geometry>
      </collision>
      <visual name='humerus_1_visual'>
        <pose frame=''>0 0 -0.028 0 -0 0</pose>
        <geometry>
          <mesh>
            <scale>1 1 1</scale>
            <uri>model://ker_description/meshes/humerus.stl</uri>
          </mesh>
        </geometry>
      </visual>
    </link>
    <joint name='humerus_1_joint' type='revolute'>
      <child>humerus_1</child>
      <parent>motor_1</parent>
      <axis>
        <xyz>0 1 0</xyz>
        <limit>
          <lower>-3.14</lower>
          <upper>3.14</upper>
          <effort>10</effort>
          <velocity>0.5</velocity>
        </limit>
        <dynamics>
          <damping>0</damping>
          <friction>0</friction>
          <spring_reference>0</spring_reference>
          <spring_stiffness>0</spring_stiffness>
        </dynamics>
        <use_parent_model_frame>1</use_parent_model_frame>
      </axis>
    </joint>
    <link name='radius_1'>
      <pose frame=''>0.073 0.036 -0.0827 0 -0 0</pose>
      <inertial>
        <pose frame=''>0 0 -0.02428 0 -0 0</pose>
        <mass>0.00992447</mass>
        <inertia>
          <ixx>2.69e-06</ixx>
          <ixy>0</ixy>
          <ixz>0</ixz>
          <iyy>1.99e-06</iyy>
          <iyz>0</iyz>
          <izz>1.22e-06</izz>
        </inertia>
      </inertial>
      <velocity_decay>
        <linear>10000000</linear>
        <angular>10000000</angular>
      </velocity_decay>
      <collision name='radius_1_collision'>
        <pose frame=''>0 0 -0.04928 0 -0 0</pose>
        <geometry>
          <sphere>
            <radius>0.01</radius>
          </sphere>
        </geometry>
        <surface>
          <contact>
            <collide_without_contact>0</collide_without_contact>
            <ode>
              <max_vel>1.2</max_vel>
              <min_depth>0</min_depth>
            </ode>
            <bullet>
              <kp>1000000</kp>
              <kd>10</kd>
            </bullet>
          </contact>
          <friction>
            <ode>
              <mu>10</mu>
              <mu2>10</mu2>
              <fdir1>1 1 0</fdir1>
            </ode>
            <bullet>
              <friction>1</friction>
              <friction2>1</friction2>
              <rolling_friction>1</rolling_friction>
              <fdir1>1 1 1</fdir1>
            </bullet>
          </friction>
        </surface>
      </collision>
      <visual name='radius_1_visual'>
        <pose frame=''>0 0 -0.01628 0 -0 0</pose>
        <geometry>
          <mesh>
            <scale>1 1 1</scale>
            <uri>model://ker_description/meshes/radius_3_dec.STL</uri>
          </mesh>
        </geometry>
      </visual>
      <gravity>1</gravity>
      <self_collide>0</self_collide>
    </link>
    <joint name='radius_1_joint' type='revolute'>
      <child>radius_1</child>
      <parent>humerus_1</parent>
      <axis>
        <xyz>0 1 0</xyz>
        <limit>
          <lower>-3.14</lower>
          <upper>3.14</upper>
          <effort>10</effort>
          <velocity>0.5</velocity>
        </limit>
        <dynamics>
          <damping>0</damping>
          <friction>0</friction>
          <spring_reference>0</spring_reference>
          <spring_stiffness>0</spring_stiffness>
        </dynamics>
        <use_parent_model_frame>1</use_parent_model_frame>
      </axis>
    </joint>
    <link name='motor_2'>
      <pose frame=''>0.073 -0.036 0.0005 0 -0 0</pose>
      <inertial>
        <pose frame=''>0 0 -0.0125 0 -0 0</pose>
        <mass>0.0082825</mass>
        <inertia>
          <ixx>1.63e-06</ixx>
          <ixy>0</ixy>
          <ixz>0</ixz>
          <iyy>1.14e-06</iyy>
          <iyz>0</iyz>
          <izz>1.03e-06</izz>
        </inertia>
      </inertial>
      <collision name='motor_2_collision'>
        <pose frame=''>0 0 -0.0125 0 -0 0</pose>
        <geometry>
          <box>
            <size>0.022 0.0344 0.0472</size>
          </box>
        </geometry>
      </collision>
      <visual name='motor_2_visual'>
        <pose frame=''>0 0 -0.0125 0 -0 0</pose>
        <geometry>
          <mesh>
            <scale>1 1 1</scale>
            <uri>model://ker_description/meshes/roll.STL</uri>
          </mesh>
        </geometry>
      </visual>
    </link>
    <joint name='motor_2_joint' type='revolute'>
      <child>motor_2</child>
      <parent>odom</parent>
      <axis>
        <xyz>1 0 0</xyz>
        <limit>
          <lower>-3.14</lower>
          <upper>3.14</upper>
          <effort>10</effort>
          <velocity>0.5</velocity>
        </limit>
        <dynamics>
          <damping>0</damping>
          <friction>0</friction>
          <spring_reference>0</spring_reference>
          <spring_stiffness>0</spring_stiffness>
        </dynamics>
        <use_parent_model_frame>1</use_parent_model_frame>
      </axis>
    </joint>
    <link name='humerus_2'>
      <pose frame=''>0.073 -0.036 -0.0267 0 -0 -3.14159</pose>
      <inertial>
        <pose frame=''>0 0 -0.028 0 -0 0</pose>
        <mass>0.0361976</mass>
        <inertia>
          <ixx>2.198e-05</ixx>
          <ixy>0</ixy>
          <ixz>4e-08</ixz>
          <iyy>2.188e-05</iyy>
          <iyz>0</iyz>
          <izz>3.91e-06</izz>
        </inertia>
      </inertial>
      <velocity_decay>
        <linear>10000000</linear>
        <angular>10000000</angular>
      </velocity_decay>
      <collision name='humerus_2_collision'>
        <pose frame=''>0 0 -0.028 0 -0 0</pose>
        <geometry>
          <box>
            <size>0.022 0.025 0.076</size>
          </box>
        </geometry>
      </collision>
      <visual name='humerus_2_visual'>
        <pose frame=''>0 0 -0.028 0 -0 0</pose>
        <geometry>
          <mesh>
            <scale>1 1 1</scale>
            <uri>model://ker_description/meshes/humerus.stl</uri>
          </mesh>
        </geometry>
      </visual>
    </link>
    <joint name='humerus_2_joint' type='revolute'>
      <child>humerus_2</child>
      <parent>motor_2</parent>
      <axis>
        <xyz>-2.06823e-13 1 0</xyz>
        <limit>
          <lower>-3.14</lower>
          <upper>3.14</upper>
          <effort>10</effort>
          <velocity>0.5</velocity>
        </limit>
        <dynamics>
          <damping>0</damping>
          <friction>0</friction>
          <spring_reference>0</spring_reference>
          <spring_stiffness>0</spring_stiffness>
        </dynamics>
        <use_parent_model_frame>1</use_parent_model_frame>
      </axis>
    </joint>
    <link name='radius_2'>
      <pose frame=''>0.073 -0.036 -0.0827 0 -0 -3.14159</pose>
      <inertial>
        <pose frame=''>0 0 -0.02428 0 -0 0</pose>
        <mass>0.00992447</mass>
        <inertia>
          <ixx>2.69e-06</ixx>
          <ixy>0</ixy>
          <ixz>0</ixz>
          <iyy>1.99e-06</iyy>
          <iyz>0</iyz>
          <izz>1.22e-06</izz>
        </inertia>
      </inertial>
      <velocity_decay>
        <linear>10000000</linear>
        <angular>10000000</angular>
      </velocity_decay>
      <collision name='radius_2_collision'>
        <pose frame=''>0 0 -0.04928 0 -0 0</pose>
        <geometry>
          <sphere>
            <radius>0.01</radius>
          </sphere>
        </geometry>
        <surface>
          <contact>
            <collide_without_contact>0</collide_without_contact>
            <ode>
              <max_vel>1.2</max_vel>
              <min_depth>0</min_depth>
            </ode>
            <bullet>
              <kp>1000000</kp>
              <kd>10</kd>
            </bullet>
          </contact>
          <friction>
            <ode>
              <mu>10</mu>
              <mu2>10</mu2>
              <fdir1>1 1 0</fdir1>
            </ode>
            <bullet>
              <friction>1</friction>
              <friction2>1</friction2>
              <rolling_friction>1</rolling_friction>
              <fdir1>1 1 1</fdir1>
            </bullet>
          </friction>
        </surface>
      </collision>
      <visual name='radius_2_visual'>
        <pose frame=''>0 0 -0.01628 0 -0 0</pose>
        <geometry>
          <mesh>
            <scale>1 1 1</scale>
            <uri>model://ker_description/meshes/radius_3_dec.STL</uri>
          </mesh>
        </geometry>
      </visual>
      <gravity>1</gravity>
      <self_collide>0</self_collide>
    </link>
    <joint name='radius_2_joint' type='revolute'>
      <child>radius_2</child>
      <parent>humerus_2</parent>
      <axis>
        <xyz>-2.06823e-13 1 0</xyz>
        <limit>
          <lower>-3.14</lower>
          <upper>3.14</upper>
          <effort>10</effort>
          <velocity>0.5</velocity>
        </limit>
        <dynamics>
          <damping>0</damping>
          <friction>0</friction>
          <spring_reference>0</spring_reference>
          <spring_stiffness>0</spring_stiffness>
        </dynamics>
        <use_parent_model_frame>1</use_parent_model_frame>
      </axis>
    </joint>
    <link name='motor_3'>
      <pose frame=''>-0.073 -0.036 0.0005 0 -0 0</pose>
      <inertial>
        <pose frame=''>0 0 -0.0125 0 -0 0</pose>
        <mass>0.0082825</mass>
        <inertia>
          <ixx>1.63e-06</ixx>
          <ixy>0</ixy>
          <ixz>0</ixz>
          <iyy>1.14e-06</iyy>
          <iyz>0</iyz>
          <izz>1.03e-06</izz>
        </inertia>
      </inertial>
      <collision name='motor_3_collision'>
        <pose frame=''>0 0 -0.0125 0 -0 0</pose>
        <geometry>
          <box>
            <size>0.022 0.0344 0.0472</size>
          </box>
        </geometry>
      </collision>
      <visual name='motor_3_visual'>
        <pose frame=''>0 0 -0.0125 0 -0 0</pose>
        <geometry>
          <mesh>
            <scale>1 1 1</scale>
            <uri>model://ker_description/meshes/roll.STL</uri>
          </mesh>
        </geometry>
      </visual>
    </link>
    <joint name='motor_3_joint' type='revolute'>
      <child>motor_3</child>
      <parent>odom</parent>
      <axis>
        <xyz>1 0 0</xyz>
        <limit>
          <lower>-3.14</lower>
          <upper>3.14</upper>
          <effort>10</effort>
          <velocity>0.5</velocity>
        </limit>
        <dynamics>
          <damping>0</damping>
          <friction>0</friction>
          <spring_reference>0</spring_reference>
          <spring_stiffness>0</spring_stiffness>
        </dynamics>
        <use_parent_model_frame>1</use_parent_model_frame>
      </axis>
    </joint>
    <link name='femur_2'>
      <pose frame=''>-0.073 -0.036 -0.0267 0 -0 -3.14159</pose>
      <inertial>
        <pose frame=''>0 0 -0.028 0 -0 0</pose>
        <mass>0.0361976</mass>
        <inertia>
          <ixx>2.198e-05</ixx>
          <ixy>0</ixy>
          <ixz>4e-08</ixz>
          <iyy>2.188e-05</iyy>
          <iyz>0</iyz>
          <izz>3.91e-06</izz>
        </inertia>
      </inertial>
       <velocity_decay>
        <linear>10000000</linear>
        <angular>10000000</angular>
      </velocity_decay>
      <collision name='femur_2_collision'>
        <pose frame=''>0 0 -0.028 0 -0 0</pose>
        <geometry>
          <box>
            <size>0.022 0.025 0.076</size>
          </box>
        </geometry>
      </collision>
      <visual name='femur_2_visual'>
        <pose frame=''>0 0 -0.028 0 -0 0</pose>
        <geometry>
          <mesh>
            <scale>1 1 0</scale>
            <uri>model://ker_description/meshes/humerus.stl</uri>
          </mesh>
        </geometry>
      </visual>
    </link>
    <joint name='femur_2_joint' type='revolute'>
      <child>femur_2</child>
      <parent>motor_3</parent>
      <axis>
        <xyz>-2.06823e-13 1 0</xyz>
        <limit>
          <lower>-3.14</lower>
          <upper>3.14</upper>
          <effort>10</effort>
          <velocity>0.5</velocity>
        </limit>
        <dynamics>
          <damping>0</damping>
          <friction>0</friction>
          <spring_reference>0</spring_reference>
          <spring_stiffness>0</spring_stiffness>
        </dynamics>
        <use_parent_model_frame>1</use_parent_model_frame>
      </axis>
    </joint>
    <link name='tibula_2'>
      <pose frame=''>-0.073 -0.036 -0.0827 0 -0 -3.14159</pose>
      <inertial>
        <pose frame=''>0 0 -0.02428 0 -0 0</pose>
        <mass>0.00992447</mass>
        <inertia>
          <ixx>2.69e-06</ixx>
          <ixy>0</ixy>
          <ixz>0</ixz>
          <iyy>1.99e-06</iyy>
          <iyz>0</iyz>
          <izz>1.22e-06</izz>
        </inertia>
      </inertial>
      <velocity_decay>
        <linear>10000000</linear>
        <angular>10000000</angular>
      </velocity_decay>
      <collision name='tibula_2_collision'>
        <pose frame=''>0 0 -0.04928 0 -0 0</pose>
        <geometry>
          <sphere>
            <radius>0.01</radius>
          </sphere>
        </geometry>
        <surface>
          <contact>
            <collide_without_contact>0</collide_without_contact>
            <ode>
              <max_vel>1.2</max_vel>
              <min_depth>0</min_depth>
            </ode>
            <bullet>
              <kp>1000000</kp>
              <kd>10</kd>
            </bullet>
          </contact>
          <friction>
            <ode>
              <mu>10</mu>
              <mu2>10</mu2>
              <fdir1>0 0 0</fdir1>
            </ode>
            <bullet>
              <friction>1</friction>
              <friction2>1</friction2>
              <rolling_friction>1</rolling_friction>
              <fdir1>1 1 1</fdir1>
            </bullet>
          </friction>
        </surface>
      </collision>
      <visual name='tibula_2_visual'>
        <pose frame=''>0 0 -0.01628 0 -0 0</pose>
        <geometry>
          <mesh>
            <scale>1 1 1</scale>
            <uri>model://ker_description/meshes/radius_3_dec.STL</uri>
          </mesh>
        </geometry>
      </visual>
      <gravity>1</gravity>
      <self_collide>0</self_collide>
    </link>
    <joint name='tibula_2_joint' type='revolute'>
      <child>tibula_2</child>
      <parent>femur_2</parent>
      <axis>
        <xyz>-2.06823e-13 1 0</xyz>
        <limit>
          <lower>-3.14</lower>
          <upper>3.14</upper>
          <effort>10</effort>
          <velocity>0.5</velocity>
        </limit>
        <dynamics>
          <damping>0</damping>
          <friction>0</friction>
          <spring_reference>0</spring_reference>
          <spring_stiffness>0</spring_stiffness>
        </dynamics>
        <use_parent_model_frame>1</use_parent_model_frame>
      </axis>
    </joint>
    <link name='motor_4'>
      <pose frame=''>-0.073 0.036 0.0005 0 -0 0</pose>
      <inertial>
        <pose frame=''>0 0 -0.0125 0 -0 0</pose>
        <mass>0.0082825</mass>
        <inertia>
          <ixx>1.63e-06</ixx>
          <ixy>0</ixy>
          <ixz>0</ixz>
          <iyy>1.14e-06</iyy>
          <iyz>0</iyz>
          <izz>1.03e-06</izz>
        </inertia>
      </inertial>
      <collision name='motor_4_collision'>
        <pose frame=''>0 0 -0.0125 0 -0 0</pose>
        <geometry>
          <box>
            <size>0.022 0.0344 0.0472</size>
          </box>
        </geometry>
      </collision>
      <visual name='motor_4_visual'>
        <pose frame=''>0 0 -0.0125 0 -0 0</pose>
        <geometry>
          <mesh>
            <scale>1 1 1</scale>
            <uri>model://ker_description/meshes/roll.STL</uri>
          </mesh>
        </geometry>
      </visual>
    </link>
    <joint name='motor_4_joint' type='revolute'>
      <child>motor_4</child>
      <parent>odom</parent>
      <axis>
        <xyz>1 0 0</xyz>
        <limit>
          <lower>-3.14</lower>
          <upper>3.14</upper>
          <effort>10</effort>
          <velocity>0.5</velocity>
        </limit>
        <dynamics>
          <damping>0</damping>
          <friction>0</friction>
          <spring_reference>0</spring_reference>
          <spring_stiffness>0</spring_stiffness>
        </dynamics>
        <use_parent_model_frame>1</use_parent_model_frame>
      </axis>
    </joint>
    <link name='femur_1'>
      <pose frame=''>-0.073 0.036 -0.0267 0 -0 0</pose>
      <inertial>
        <pose frame=''>0 0 -0.028 0 -0 0</pose>
        <mass>0.0361976</mass>
        <inertia>
          <ixx>2.198e-05</ixx>
          <ixy>0</ixy>
          <ixz>4e-08</ixz>
          <iyy>2.188e-05</iyy>
          <iyz>0</iyz>
          <izz>3.91e-06</izz>
        </inertia>
      </inertial>
      <velocity_decay>
        <linear>10000000</linear>
        <angular>10000000</angular>
      </velocity_decay>
      <collision name='femur_1_collision'>
        <pose frame=''>0 0 -0.028 0 -0 0</pose>
        <geometry>
          <box>
            <size>0.022 0.025 0.076</size>
          </box>
        </geometry>
      </collision>
      <visual name='femur_1_visual'>
        <pose frame=''>0 0 -0.028 0 -0 0</pose>
        <geometry>
          <mesh>
            <scale>1 1 1</scale>
            <uri>model://ker_description/meshes/humerus.stl</uri>
          </mesh>
        </geometry>
      </visual>
    </link>
    <joint name='femur_1_joint' type='revolute'>
      <child>femur_1</child>
      <parent>motor_4</parent>
      <axis>
        <xyz>0 1 0</xyz>
        <limit>
          <lower>-3.14</lower>
          <upper>3.14</upper>
          <effort>10</effort>
          <velocity>0.5</velocity>
        </limit>
        <dynamics>
          <damping>0</damping>
          <friction>0</friction>
          <spring_reference>0</spring_reference>
          <spring_stiffness>0</spring_stiffness>
        </dynamics>
        <use_parent_model_frame>1</use_parent_model_frame>
      </axis>
    </joint>
    <link name='tibula_1'>
      <pose frame=''>-0.073 0.036 -0.0827 0 -0 0</pose>
      <inertial>
        <pose frame=''>0 0 -0.02428 0 -0 0</pose>
        <mass>0.00992447</mass>
        <inertia>
          <ixx>2.69e-06</ixx>
          <ixy>0</ixy>
          <ixz>0</ixz>
          <iyy>1.99e-06</iyy>
          <iyz>0</iyz>
          <izz>1.22e-06</izz>
        </inertia>
      </inertial>
      <velocity_decay>
        <linear>10000000</linear>
        <angular>10000000</angular>
      </velocity_decay>
      <collision name='tibula_1_collision'>
        <pose frame=''>0 0 -0.04928 0 -0 0</pose>
        <geometry>
          <sphere>
            <radius>0.01</radius>
          </sphere>
        </geometry>
        <surface>
          <contact>
            <collide_without_contact>0</collide_without_contact>
            <ode>
              <max_vel>1.2</max_vel>
              <min_depth>0</min_depth>
            </ode>
            <bullet>
              <kp>1000000</kp>
              <kd>10</kd>
            </bullet>
          </contact>
          <friction>
            <ode>
              <mu>10</mu>
              <mu2>10</mu2>
              <fdir1>0 0 0</fdir1>
            </ode>
            <bullet>
              <friction>1</friction>
              <friction2>1</friction2>
              <rolling_friction>1</rolling_friction>
              <fdir1>1 1 1</fdir1>
            </bullet>
          </friction>
        </surface>
      </collision>
      <visual name='tibula_1_visual'>
        <pose frame=''>0 0 -0.01628 0 -0 0</pose>
        <geometry>
          <mesh>
            <scale>1 1 1</scale>
            <uri>model://ker_description/meshes/radius_3_dec.STL</uri>
          </mesh>
        </geometry>
      </visual>
      <gravity>1</gravity>
      <self_collide>0</self_collide>
    </link>
    <joint name='tibula_1_joint' type='revolute'>
      <child>tibula_1</child>
      <parent>femur_1</parent>
      <axis>
        <xyz>0 1 0</xyz>
        <limit>
          <lower>-3.14</lower>
          <upper>3.14</upper>
          <effort>10</effort>
          <velocity>0.5</velocity>
        </limit>
        <dynamics>
          <damping>0</damping>
          <friction>0</friction>
          <spring_reference>0</spring_reference>
          <spring_stiffness>0</spring_stiffness>
        </dynamics>
        <use_parent_model_frame>1</use_parent_model_frame>
      </axis>
    </joint>
    <static>0</static>
    <plugin name='gazebo_ros_control' filename='libgazebo_ros_control.so'>
      <robotParam>robot_description</robotParam>
    </plugin>
  </model>
</sdf>
