<?xml version='1.0'?>
  <robot name="my_robot">
    <link name="body">
        <inertial>
            <origin xyz="0 0 0.15" rpy="0 0 0"/>
            <mass value="1"/>
            <inertia ixx="1" ixy="0" ixz="0" iyy="1" iyz="0" izz="1" />
        </inertial>

        <collision>
          <origin xyz="0 0 0.15" rpy="0 0 0"/>
          <geometry>
            <box size="0.25 0.15 0.02"/>
          </geometry>
        </collision>

        <visual>
          <origin xyz="0 0 0.15" rpy="0 0 0"/>
          <geometry>
            <box size = "0.25 0.15 0.02"/>
          </geometry>
        </visual>
    </link>

    <link name="motor_1">
        <inertial>
            <origin xyz="0 0 -0.0085" rpy="0 0 0"/>
            <mass value="1"/>
            <inertia ixx="1" ixy="0" ixz="0" iyy="1" iyz="0" izz="1" />
        </inertial>

        <collision>
          <origin xyz="0 0 -0.0085" rpy="0 0 0"/>
          <geometry>
            <box size="0.022 0.025 0.037"/>
          </geometry>
        </collision>

        <visual>
          <origin xyz="0 0 -0.0085" rpy="0 0 0"/>
          <geometry>
            <box size = "0.022 0.025 0.037"/>
          </geometry>
        </visual>
    </link>

    <link name="motor_2">
        <inertial>
            <origin xyz="0 0 -0.0085" rpy="0 0 0"/>
            <mass value="1"/>
            <inertia ixx="1" ixy="0" ixz="0" iyy="1" iyz="0" izz="1" />
        </inertial>

        <collision>
          <origin xyz="0 0 -0.0085" rpy="0 0 0"/>
          <geometry>
            <box size="0.022 0.025 0.037"/>
          </geometry>
        </collision>

        <visual>
          <origin xyz="0 0 -0.0085" rpy="0 0 0"/>
          <geometry>
            <box size = "0.022 0.025 0.037"/>
          </geometry>
        </visual>
    </link>

    <link name="motor_3">
        <inertial>
            <origin xyz="-0 0 -0.0085" rpy="0 0 0"/>
            <mass value="1"/>
            <inertia ixx="1" ixy="0" ixz="0" iyy="1" iyz="0" izz="1" />
        </inertial>

        <collision>
          <origin xyz="0 0 -0.0085" rpy="0 0 0"/>
          <geometry>
            <box size="0.022 0.025 0.037"/>
          </geometry>
        </collision>

        <visual>
          <origin xyz="0 0 -0.0085" rpy="0 0 0"/>
          <geometry>
            <box size = "0.022 0.025 0.037"/>
          </geometry>
        </visual>
    </link>

    <link name="motor_4">
        <inertial>
            <origin xyz="0 0 -0.0085" rpy="0 0 0"/>
            <mass value="1"/>
            <inertia ixx="1" ixy="0" ixz="0" iyy="1" iyz="0" izz="1" />
        </inertial>

        <collision>
          <origin xyz="0 0 -0.0085" rpy="0 0 0"/>
          <geometry>
            <box size="0.022 0.025 0.037"/>
          </geometry>
        </collision>

        <visual>
          <origin xyz="0 0 -0.0085" rpy="0 0 0"/>
          <geometry>
            <box size = "0.022 0.025 0.037"/>
          </geometry>
        </visual>
    </link>

    <joint name="motor_joint_1" type="fixed">
        <origin xyz="0.114 0.0875 0.10" rpy="0 0 0"/>
        <parent link="body"/>
        <child link="motor_1"/>
    </joint>

    <joint name="motor_joint_2" type="fixed">
        <origin xyz="0.114 -0.0875 0.10" rpy="0 0 0"/>
        <parent link="body"/>
        <child link="motor_2"/>
    </joint>
    <joint name="motor_joint_3" type="fixed">
        <origin xyz="-0.114 -0.0875 0.10" rpy="0 0 0"/>
        <parent link="body"/>
        <child link="motor_3"/>
    </joint>
    <joint name="motor_joint_4" type="fixed">
        <origin xyz="-0.114 0.0875 0.10" rpy="0 0 0"/>
        <parent link="body"/>
        <child link="motor_4"/>
    </joint>

    <link name="humerus_1">
        <inertial>
            <origin xyz="0 0 -0.1" rpy="0 0 0"/>
            <mass value="1"/>
            <inertia ixx="1" ixy="0" ixz="0" iyy="1" iyz="0" izz="1" />
        </inertial>

        <collision>
          <origin xyz="0 0 -0.1" rpy="0 0 0"/>
          <geometry>
            <box size="0.022 0.025 0.08"/>
          </geometry>
        </collision>

        <visual>
          <origin xyz="0 0 -0.1" rpy="0 0 0"/>
          <geometry>
            <box size = "0.022 0.025 0.08"/>
          </geometry>
        </visual>
    </link>

    <link name="humerus_2">
        <inertial>
            <origin xyz="0 0 -0.1" rpy="0 0 0"/>
            <mass value="1"/>
            <inertia ixx="1" ixy="0" ixz="0" iyy="1" iyz="0" izz="1" />
        </inertial>

        <collision>
          <origin xyz="0 0 -0.1" rpy="0 0 0"/>
          <geometry>
            <box size="0.022 0.025 0.08"/>
          </geometry>
        </collision>

        <visual>
          <origin xyz="0 0 -0.1" rpy="0 0 0"/>
          <geometry>
            <box size = "0.022 0.025 0.08"/>
          </geometry>
        </visual>
    </link>

    <link name="femur_2">
        <inertial>
            <origin xyz="0 0 -0.1" rpy="0 0 0"/>
            <mass value="1"/>
            <inertia ixx="1" ixy="0" ixz="0" iyy="1" iyz="0" izz="1" />
        </inertial>

        <collision>
          <origin xyz="0 0 -0.1" rpy="0 0 0"/>
          <geometry>
            <box size="0.022 0.025 0.08"/>
          </geometry>
        </collision>

        <visual>
          <origin xyz="0 0 -0.1" rpy="0 0 0"/>
          <geometry>
            <box size = "0.022 0.025 0.08"/>
          </geometry>
        </visual>
    </link>

    <link name="femur_1">
        <inertial>
            <origin xyz="0 0 -0.1" rpy="0 0 0"/>
            <mass value="1"/>
            <inertia ixx="1" ixy="0" ixz="0" iyy="1" iyz="0" izz="1" />
        </inertial>

        <collision>
          <origin xyz="0 0 -0.1" rpy="0 0 0"/>
          <geometry>
            <box size="0.022 0.025 0.08"/>
          </geometry>
        </collision>

        <visual>
          <origin xyz="0 0 -0.1" rpy="0 0 0"/>
          <geometry>
            <box size = "0.022 0.025 0.08"/>
          </geometry>
        </visual>
    </link>

    <joint name="humerus_joint_1" type="revolute">
        <origin xyz="0 0 0.045" rpy="0 0 0"/>
        <parent link="motor_1"/>
        <child link="humerus_1"/>
        <axis xyz="0 1 0"/>
        <dynamics damping="0.1" friction="0.1"/>
        <limit effort="3.0" velocity="3.0" lower="0.0" upper="3.14"/>
    </joint>

    <joint name="humerus_joint_2" type="revolute">
        <origin xyz="0 0 0.045" rpy="0 0 0"/>
        <parent link="motor_2"/>
        <child link="humerus_2"/>
        <axis xyz="0 1 0"/>
        <dynamics damping="0.1" friction="0.1"/>
        <limit effort="3.0" velocity="3.0" lower="0.0" upper="3.14"/>
    </joint>

    <joint name="femur_joint_2" type="revolute">
        <origin xyz="0 0 0.045" rpy="0 0 0"/>
        <parent link="motor_3"/>
        <child link="femur_2"/>
        <axis xyz="0 1 0"/>
        <dynamics damping="0.1" friction="0.1"/>
        <limit effort="3.0" velocity="3.0" lower="0.0" upper="3.14"/>
    </joint>

    <joint name="femur_joint_1" type="revolute">
        <origin xyz="0 0 0.045" rpy="0 0 0"/>
        <parent link="motor_4"/>
        <child link="femur_1"/>
        <axis xyz="0 1 0"/>
        <dynamics damping="0.1" friction="0.1"/>
        <limit effort="3.0" velocity="3.0" lower="0.0" upper="3.14"/>
    </joint>

    <link name="motor_1b">
        <inertial>
            <origin xyz="0 0 0" rpy="0 0 0"/>
            <mass value="1"/>
            <inertia ixx="1" ixy="0" ixz="0" iyy="1" iyz="0" izz="1" />
        </inertial>

        <collision>
          <origin xyz="0 0 0" rpy="0 0 0"/>
          <geometry>
            <box size="0.022 0.025 0.037"/>
          </geometry>
        </collision>

        <visual>
          <origin xyz="0 0 0" rpy="0 0 0"/>
          <geometry>
            <box size = "0.022 0.025 0.037"/>
          </geometry>
        </visual>      
    </link>

    <link name="motor_2b">
           <inertial>
            <origin xyz="0 0 0" rpy="0 0 0"/>
            <mass value="1"/>
            <inertia ixx="1" ixy="0" ixz="0" iyy="1" iyz="0" izz="1" />
        </inertial>

        <collision>
          <origin xyz="0 0 0" rpy="0 0 0"/>
          <geometry>
            <box size="0.022 0.025 0.037"/>
          </geometry>
        </collision>

        <visual>
          <origin xyz="0 0 0" rpy="0 0 0"/>
          <geometry>
            <box size = "0.022 0.025 0.037"/>
          </geometry>
        </visual>     
    </link>

    <link name="motor_3b">
        <inertial>
            <origin xyz="0 0 0" rpy="0 0 0"/>
            <mass value="1"/>
            <inertia ixx="1" ixy="0" ixz="0" iyy="1" iyz="0" izz="1" />
        </inertial>

        <collision>
          <origin xyz="0 0 0" rpy="0 0 0"/>
          <geometry>
            <box size="0.022 0.025 0.037"/>
          </geometry>
        </collision>

        <visual>
          <origin xyz="0 0 0" rpy="0 0 0"/>
          <geometry>
            <box size = "0.022 0.025 0.037"/>
          </geometry>
        </visual>     
    </link>

    <link name="motor_4b">
        <inertial>
            <origin xyz="0 0 0" rpy="0 0 0"/>
            <mass value="1"/>
            <inertia ixx="1" ixy="0" ixz="0" iyy="1" iyz="0" izz="1" />
        </inertial>

        <collision>
          <origin xyz="0 0 0" rpy="0 0 0"/>
          <geometry>
            <box size="0.022 0.025 0.037"/>
          </geometry>
        </collision>

        <visual>
          <origin xyz="0 0 0" rpy="0 0 0"/>
          <geometry>
            <box size = "0.022 0.025 0.037"/>
          </geometry>
        </visual>     
    </link>

    <joint name="motor_joint_1b" type="fixed">
        <origin xyz="0 0 -0.15" rpy="0 0 0"/>
        <parent link="humerus_1"/>
        <child link="motor_1b"/>
    </joint>

    <joint name="motor_joint_2b" type="fixed">
        <origin xyz="0 0 -0.15" rpy="0 0 0"/>
        <parent link="humerus_2"/>
        <child link="motor_2b"/>
    </joint>

    <joint name="motor_joint_3b" type="fixed">
        <origin xyz="0 0 -0.15" rpy="0 0 0"/>
        <parent link="femur_2"/>
        <child link="motor_3b"/>
    </joint>

    <joint name="motor_joint_4b" type="fixed">
        <origin xyz="0 0 -0.15" rpy="0 0 0"/>
        <parent link="femur_1"/>
        <child link="motor_4b"/>
    </joint>

    <link name="radius_1">
        <inertial>
            <origin xyz="0 0 0" rpy="0 0 0"/>
            <mass value="1"/>
            <inertia ixx="1" ixy="0" ixz="0" iyy="1" iyz="0" izz="1" />
        </inertial>

        <collision>
          <origin xyz="0 0 0" rpy="0 0 0"/>
          <geometry>
            <box size="0.022 0.025 0.08"/>
          </geometry>
        </collision>

        <visual>
          <origin xyz="0 0 0" rpy="0 0 0"/>
          <geometry>
            <box size = "0.022 0.025 0.08"/>
          </geometry>
        </visual>  
    </link>

    <link name="radius_2">
       <inertial>
            <origin xyz="0 0 0" rpy="0 0 0"/>
            <mass value="1"/>
            <inertia ixx="1" ixy="0" ixz="0" iyy="1" iyz="0" izz="1" />
        </inertial>

        <collision>
          <origin xyz="0 0 0" rpy="0 0 0"/>
          <geometry>
            <box size="0.022 0.025 0.08"/>
          </geometry>
        </collision>

        <visual>
          <origin xyz="0 0 0" rpy="0 0 0"/>
          <geometry>
            <box size = "0.022 0.025 0.08"/>
          </geometry>
        </visual>  
    </link>

    <link name="tibula_2">
       <inertial>
            <origin xyz="0 0 0" rpy="0 0 0"/>
            <mass value="1"/>
            <inertia ixx="1" ixy="0" ixz="0" iyy="1" iyz="0" izz="1" />
        </inertial>

        <collision>
          <origin xyz="0 0 0" rpy="0 0 0"/>
          <geometry>
            <box size="0.022 0.025 0.08"/>
          </geometry>
        </collision>

        <visual>
          <origin xyz="0 0 0" rpy="0 0 0"/>
          <geometry>
            <box size = "0.022 0.025 0.08"/>
          </geometry>
        </visual>  
    </link>

    <link name="tibula_1">
       <inertial>
            <origin xyz="0 0 0" rpy="0 0 0"/>
            <mass value="1"/>
            <inertia ixx="1" ixy="0" ixz="0" iyy="1" iyz="0" izz="1" />
        </inertial>

        <collision>
          <origin xyz="0 0 0" rpy="0 0 0"/>
          <geometry>
            <box size="0.022 0.025 0.08"/>
          </geometry>
        </collision>

        <visual>
          <origin xyz="0 0 0" rpy="0 0 0"/>
          <geometry>
            <box size = "0.022 0.025 0.08"/>
          </geometry>
        </visual>  
    </link>

    <joint name="radius_joint_1" type="revolute">
        <origin xyz="0 0 -.0345" rpy="0 0 0"/>
        <parent link="motor_1b"/>
        <child link="radius_1"/>
        <axis xyz="0 1 0"/>
        <dynamics damping="0.1" friction="0.1"/>
        <limit effort="10.0" velocity="3.0" lower="0.0" upper="3.14"/>
    </joint>

    <joint name="radius_joint_2" type="revolute">
        <origin xyz="0 0 -.0345" rpy="0 0 0"/>
        <parent link="motor_2b"/>
        <child link="radius_2"/>
        <axis xyz="0 1 0"/>
        <dynamics damping="0.1" friction="0.1"/>
        <limit effort="10.0" velocity="3.0" lower="0.0" upper="3.14"/>
    </joint>

    <joint name="tibula_joint_2" type="revolute">
        <origin xyz="0 0 -.0345" rpy="0 0 0"/>
        <parent link="motor_3b"/>
        <child link="tibula_2"/>
        <axis xyz="0 1 0"/>
        <dynamics damping="0.1" friction="0.1"/>
        <limit effort="10.0" velocity="3.0" lower="0.0" upper="3.14"/>
    </joint>

    <joint name="tibula_joint_1" type="revolute">
        <origin xyz="0 0 -.0345" rpy="0 0 0"/>
        <parent link="motor_4b"/>
        <child link="tibula_1"/>
        <axis xyz="0 1 0"/>
        <dynamics damping="0.1" friction="0.1"/>
        <limit effort="10.0" velocity="3.0" lower="0.0" upper="3.14"/>
    </joint>
  </robot>
