<?xml version="1.0" ?>
<!-- =================================================================================== -->
<!-- |    This document was autogenerated by xacro from ker2.urdf.xacro                | -->
<!-- |    EDITING THIS FILE BY HAND IS NOT RECOMMENDED                                 | -->
<!-- =================================================================================== -->
<robot name="ker" xmlns:xacro="http://www.ros.org/wiki/xacro">
  <physics type="ode" update_rate="100">
    <gravity xyz="0 0 -9.81"/>
    <ode>
      <solver dt="0.01" iters="100" sor="1.3" type="world"/>
    </ode>
  </physics>
  <!--TRANSMISSION-->
  <!--DEFAULT INERTIAL PARAMETERS-->
  <!--DYNAMIXEL INERTIAL PARAMETERS-->
  <!--HUMERUS AND FEMUR INERTIAL PARAMETERS-->
  <!--JOINT OPTION PRESETS-->
  <!--MOTOR (CORONA)-->
  <!--MOTOR (DYNAMIXEL)-->
  <!--HUMERUS-->
  <!--FEMUR-->
  <!--RADIUS-->
  <!--TIBULA-->
  <!--BODY-->
  <link name="body">
    <inertial>
      <mass value="10"/>
      <inertia ixx="0.001" ixy="0.0" ixz="0.0" iyy="0.001" iyz="0.0" izz="0.001"/>
    </inertial>
    <collision>
      <origin rpy="0 0 0" xyz="0 0 0.0"/>
      <geometry>
        <mesh filename="package://ker_description/meshes/start4_1.stl" scale="1 1 1"/>
      </geometry>
    </collision>
    <visual>
      <origin rpy="0 0 0" xyz="0 0 0.0"/>
      <geometry>
        <!--box size = "${bodylen} ${bodywidth} ${bodyheight}"/-->
        <mesh filename="package://ker_description/meshes/start4_1.stl" scale="1 1 1"/>
      </geometry>
    </visual>
  </link>
  <!--EXECUTE MACROS-->
  <link name="big_motor_1">
    <inertial>
      <mass value="0.1"/>
      <inertia ixx="0.001" ixy="0.0" ixz="0.0" iyy="0.001" iyz="0.0" izz="0.001"/>
    </inertial>
    <visual>
      <geometry>
        <box size="0.051 0.025 0.053"/>
      </geometry>
      <origin rpy="1.57075 0 0" xyz="0 0 0"/>
    </visual>
    <collision>
      <geometry>
        <box size="0.051 0.025 0.053"/>
      </geometry>
      <origin rpy="0 0 0" xyz="0 0 0"/>
    </collision>
  </link>
  <joint name="big_motor_1_joint" type="fixed">
    <parent link="body"/>
    <child link="big_motor_1"/>
    <origin rpy="0 0 0" xyz="0.049 0.0345 -0.0095"/>
  </joint>
  <link name="big_motor_2">
    <inertial>
      <mass value="0.1"/>
      <inertia ixx="0.001" ixy="0.0" ixz="0.0" iyy="0.001" iyz="0.0" izz="0.001"/>
    </inertial>
    <visual>
      <geometry>
        <box size="0.051 0.025 0.053"/>
      </geometry>
      <origin rpy="1.57075 0 0" xyz="0 0 0"/>
    </visual>
    <collision>
      <geometry>
        <box size="0.051 0.025 0.053"/>
      </geometry>
      <origin rpy="0 0 0" xyz="0 0 0"/>
    </collision>
  </link>
  <joint name="big_motor_2_joint" type="fixed">
    <parent link="body"/>
    <child link="big_motor_2"/>
    <origin rpy="0 0 0" xyz="0.049 -0.0345 -0.011"/>
  </joint>
  <link name="big_motor_3">
    <inertial>
      <mass value="0.1"/>
      <inertia ixx="0.001" ixy="0.0" ixz="0.0" iyy="0.001" iyz="0.0" izz="0.001"/>
    </inertial>
    <visual>
      <geometry>
        <box size="0.051 0.025 0.053"/>
      </geometry>
      <origin rpy="1.57075 0 0" xyz="0 0 0"/>
    </visual>
    <collision>
      <geometry>
        <box size="0.051 0.025 0.053"/>
      </geometry>
      <origin rpy="0 0 0" xyz="0 0 0"/>
    </collision>
  </link>
  <joint name="big_motor_3_joint" type="fixed">
    <parent link="body"/>
    <child link="big_motor_3"/>
    <origin rpy="0 0 0" xyz="-0.049 -0.0345 -0.011"/>
  </joint>
  <link name="big_motor_4">
    <inertial>
      <mass value="0.1"/>
      <inertia ixx="0.001" ixy="0.0" ixz="0.0" iyy="0.001" iyz="0.0" izz="0.001"/>
    </inertial>
    <visual>
      <geometry>
        <box size="0.051 0.025 0.053"/>
      </geometry>
      <origin rpy="1.57075 0 0" xyz="0 0 0"/>
    </visual>
    <collision>
      <geometry>
        <box size="0.051 0.025 0.053"/>
      </geometry>
      <origin rpy="0 0 0" xyz="0 0 0"/>
    </collision>
  </link>
  <joint name="big_motor_4_joint" type="fixed">
    <parent link="body"/>
    <child link="big_motor_4"/>
    <origin rpy="0 0 0" xyz="-0.049 0.0345 -0.011"/>
  </joint>
  <link name="motor_1">
    <inertial>
      <mass value="0.00167"/>
      <inertia ixx="0.00208333325" ixy="0.0" ixz="0.0" iyy="0.00183333326" iyz="0.0" izz="0.00183333326"/>
    </inertial>
    <visual>
      <geometry>
        <box size="0.022 0.025 0.037"/>
      </geometry>
      <origin rpy="0 0 0" xyz="0 0 0"/>
      <material name="blue">
        <color rgba="0 0 .8 1"/>
      </material>
    </visual>
    <collision>
      <geometry>
        <box size="0.022 0.025 0.037"/>
      </geometry>
      <origin rpy="0 0 0" xyz="0 0 0"/>
    </collision>
  </link>
  <joint name="motor_1_joint" type="revolute">
    <parent link="big_motor_1"/>
    <child link="motor_1"/>
    <origin rpy="0 0 0" xyz="0.0365 0 0"/>
    <axis xyz="1 0 0"/>
    <dynamics damping="0.1" friction="0.1"/>
    <limit effort="3.0" lower="-3.15" upper="3.15" velocity="0.5"/>
  </joint>
  <transmission name="motor_1_joint_transmission">
    <type>transmission_interface/SimpleTransmission</type>
    <joint name="motor_1_joint">
      <hardwareInterface>PositionJointInterface</hardwareInterface>
    </joint>
    <actuator name="motor_1_joint_motor">
      <mechanicalReduction>1</mechanicalReduction>
    </actuator>
  </transmission>
  <link name="motor_2">
    <inertial>
      <mass value="0.00167"/>
      <inertia ixx="0.00208333325" ixy="0.0" ixz="0.0" iyy="0.00183333326" iyz="0.0" izz="0.00183333326"/>
    </inertial>
    <visual>
      <geometry>
        <box size="0.022 0.025 0.037"/>
      </geometry>
      <origin rpy="0 0 0" xyz="0 0 0"/>
      <material name="blue">
        <color rgba="0 0 .8 1"/>
      </material>
    </visual>
    <collision>
      <geometry>
        <box size="0.022 0.025 0.037"/>
      </geometry>
      <origin rpy="0 0 0" xyz="0 0 0"/>
    </collision>
  </link>
  <joint name="motor_2_joint" type="revolute">
    <parent link="big_motor_2"/>
    <child link="motor_2"/>
    <origin rpy="0 0 0" xyz="0.0365 0 0"/>
    <axis xyz="1 0 0"/>
    <dynamics damping="0.1" friction="0.1"/>
    <limit effort="3.0" lower="-3.15" upper="3.15" velocity="0.5"/>
  </joint>
  <transmission name="motor_2_joint_transmission">
    <type>transmission_interface/SimpleTransmission</type>
    <joint name="motor_2_joint">
      <hardwareInterface>PositionJointInterface</hardwareInterface>
    </joint>
    <actuator name="motor_2_joint_motor">
      <mechanicalReduction>1</mechanicalReduction>
    </actuator>
  </transmission>
  <link name="motor_3">
    <inertial>
      <mass value="0.00167"/>
      <inertia ixx="0.00208333325" ixy="0.0" ixz="0.0" iyy="0.00183333326" iyz="0.0" izz="0.00183333326"/>
    </inertial>
    <visual>
      <geometry>
        <box size="0.022 0.025 0.037"/>
      </geometry>
      <origin rpy="0 0 0" xyz="0 0 0"/>
      <material name="blue">
        <color rgba="0 0 .8 1"/>
      </material>
    </visual>
    <collision>
      <geometry>
        <box size="0.022 0.025 0.037"/>
      </geometry>
      <origin rpy="0 0 0" xyz="0 0 0"/>
    </collision>
  </link>
  <joint name="motor_3_joint" type="revolute">
    <parent link="big_motor_3"/>
    <child link="motor_3"/>
    <origin rpy="0 0 0" xyz="0.0365 0 0"/>
    <axis xyz="1 0 0"/>
    <dynamics damping="0.1" friction="0.1"/>
    <limit effort="3.0" lower="-3.15" upper="3.15" velocity="0.5"/>
  </joint>
  <transmission name="motor_3_joint_transmission">
    <type>transmission_interface/SimpleTransmission</type>
    <joint name="motor_3_joint">
      <hardwareInterface>PositionJointInterface</hardwareInterface>
    </joint>
    <actuator name="motor_3_joint_motor">
      <mechanicalReduction>1</mechanicalReduction>
    </actuator>
  </transmission>
  <link name="motor_4">
    <inertial>
      <mass value="0.00167"/>
      <inertia ixx="0.00208333325" ixy="0.0" ixz="0.0" iyy="0.00183333326" iyz="0.0" izz="0.00183333326"/>
    </inertial>
    <visual>
      <geometry>
        <box size="0.022 0.025 0.037"/>
      </geometry>
      <origin rpy="0 0 0" xyz="0 0 0"/>
      <material name="blue">
        <color rgba="0 0 .8 1"/>
      </material>
    </visual>
    <collision>
      <geometry>
        <box size="0.022 0.025 0.037"/>
      </geometry>
      <origin rpy="0 0 0" xyz="0 0 0"/>
    </collision>
  </link>
  <joint name="motor_4_joint" type="revolute">
    <parent link="big_motor_4"/>
    <child link="motor_4"/>
    <origin rpy="0 0 0" xyz="0.0365 0 0"/>
    <axis xyz="1 0 0"/>
    <dynamics damping="0.1" friction="0.1"/>
    <limit effort="3.0" lower="-3.15" upper="3.15" velocity="0.5"/>
  </joint>
  <transmission name="motor_4_joint_transmission">
    <type>transmission_interface/SimpleTransmission</type>
    <joint name="motor_4_joint">
      <hardwareInterface>PositionJointInterface</hardwareInterface>
    </joint>
    <actuator name="motor_4_joint_motor">
      <mechanicalReduction>1</mechanicalReduction>
    </actuator>
  </transmission>
  <link name="humerus_1">
    <inertial>
      <mass value="0.00167"/>
      <inertia ixx="0.00208333325" ixy="0.0" ixz="0.0" iyy="0.00183333326" iyz="0.0" izz="0.00183333326"/>
    </inertial>
    <collision>
      <origin rpy="0 0 0" xyz="0 0 -0.0565"/>
      <geometry>
        <box size="0.022 0.025 0.076"/>
      </geometry>
    </collision>
    <visual>
      <origin rpy="0 0 0" xyz="0 0 -0.0565"/>
      <geometry>
        <box size="0.022 0.025 0.076"/>
      </geometry>
    </visual>
  </link>
  <joint name="humerus_1_joint" type="revolute">
    <parent link="motor_1"/>
    <child link="humerus_1"/>
    <origin rpy="0 0 0" xyz="0 0 0"/>
    <axis xyz="0 1 0"/>
    <dynamics damping="0.1" friction="0.1"/>
    <limit effort="3.0" lower="-3.15" upper="3.15" velocity="0.5"/>
  </joint>
  <transmission name="humerus_1_joint_transmission">
    <type>transmission_interface/SimpleTransmission</type>
    <joint name="humerus_1_joint">
      <hardwareInterface>PositionJointInterface</hardwareInterface>
    </joint>
    <actuator name="humerus_1_joint_motor">
      <mechanicalReduction>1</mechanicalReduction>
    </actuator>
  </transmission>
  <link name="humerus_2">
    <inertial>
      <mass value="0.00167"/>
      <inertia ixx="0.00208333325" ixy="0.0" ixz="0.0" iyy="0.00183333326" iyz="0.0" izz="0.00183333326"/>
    </inertial>
    <collision>
      <origin rpy="0 0 0" xyz="0 0 -0.0565"/>
      <geometry>
        <box size="0.022 0.025 0.076"/>
      </geometry>
    </collision>
    <visual>
      <origin rpy="0 0 0" xyz="0 0 -0.0565"/>
      <geometry>
        <box size="0.022 0.025 0.076"/>
      </geometry>
    </visual>
  </link>
  <joint name="humerus_2_joint" type="revolute">
    <parent link="motor_2"/>
    <child link="humerus_2"/>
    <origin rpy="0 0 0" xyz="0 0 0"/>
    <axis xyz="0 -1 0"/>
    <dynamics damping="0.1" friction="0.1"/>
    <limit effort="3.0" lower="-3.15" upper="3.15" velocity="0.5"/>
  </joint>
  <transmission name="humerus_2_joint_transmission">
    <type>transmission_interface/SimpleTransmission</type>
    <joint name="humerus_2_joint">
      <hardwareInterface>PositionJointInterface</hardwareInterface>
    </joint>
    <actuator name="humerus_2_joint_motor">
      <mechanicalReduction>1</mechanicalReduction>
    </actuator>
  </transmission>
  <link name="femur_2">
    <inertial>
      <mass value="0.00167"/>
      <inertia ixx="0.00208333325" ixy="0.0" ixz="0.0" iyy="0.00183333326" iyz="0.0" izz="0.00183333326"/>
    </inertial>
    <collision>
      <origin rpy="0 0 0" xyz="0 0 -0.0565"/>
      <geometry>
        <box size="0.022 0.025 0.076"/>
      </geometry>
    </collision>
    <visual>
      <origin rpy="0 0 0" xyz="0 0 -0.0565"/>
      <geometry>
        <box size="0.022 0.025 0.076"/>
      </geometry>
    </visual>
  </link>
  <joint name="femur_2_joint" type="revolute">
    <parent link="motor_3"/>
    <child link="femur_2"/>
    <origin rpy="0 0 0" xyz="0 0 0"/>
    <axis xyz="0 -1 0"/>
    <dynamics damping="0.1" friction="0.1"/>
    <limit effort="3.0" lower="-3.15" upper="3.15" velocity="0.5"/>
  </joint>
  <transmission name="femur_2_joint_transmission">
    <type>transmission_interface/SimpleTransmission</type>
    <joint name="femur_2_joint">
      <hardwareInterface>PositionJointInterface</hardwareInterface>
    </joint>
    <actuator name="femur_2_joint_motor">
      <mechanicalReduction>1</mechanicalReduction>
    </actuator>
  </transmission>
  <link name="femur_1">
    <inertial>
      <mass value="0.00167"/>
      <inertia ixx="0.00208333325" ixy="0.0" ixz="0.0" iyy="0.00183333326" iyz="0.0" izz="0.00183333326"/>
    </inertial>
    <collision>
      <origin rpy="0 0 0" xyz="0 0 -0.0565"/>
      <geometry>
        <box size="0.022 0.025 0.076"/>
      </geometry>
    </collision>
    <visual>
      <origin rpy="0 0 0" xyz="0 0 -0.0565"/>
      <geometry>
        <box size="0.022 0.025 0.076"/>
      </geometry>
    </visual>
  </link>
  <joint name="femur_1_joint" type="revolute">
    <parent link="motor_4"/>
    <child link="femur_1"/>
    <origin rpy="0 0 0" xyz="0 0 0"/>
    <axis xyz="0 1 0"/>
    <dynamics damping="0.1" friction="0.1"/>
    <limit effort="3.0" lower="-3.15" upper="3.15" velocity="0.5"/>
  </joint>
  <transmission name="femur_1_joint_transmission">
    <type>transmission_interface/SimpleTransmission</type>
    <joint name="femur_1_joint">
      <hardwareInterface>PositionJointInterface</hardwareInterface>
    </joint>
    <actuator name="femur_1_joint_motor">
      <mechanicalReduction>1</mechanicalReduction>
    </actuator>
  </transmission>
  <!--xacro:motor name="motor_1b"> 
        <xacro:fixed name="motor_1b" pname="humerus_1" origin="0 0 -${humerusheight}" /> 
    </xacro:motor>
    <xacro:motor name="motor_2b"> 
        <xacro:fixed name="motor_2b" pname="humerus_2" origin="0 0 -${humerusheight}" /> 
    </xacro:motor>
    <xacro:motor name="motor_3b"> 
        <xacro:fixed name="motor_3b" pname="femur_2" origin="0 0 -${femurheight}" /> 
    </xacro:motor>
    <xacro:motor name="motor_4b"> 
        <xacro:fixed name="motor_4b" pname="femur_1" origin="0 0 -${femurheight}" /> 
    </xacro:motor-->
  <link name="radius_1">
    <inertial>
      <mass value="1"/>
      <inertia ixx="0.001" ixy="0.0" ixz="0.0" iyy="0.001" iyz="0.0" izz="0.001"/>
    </inertial>
    <collision>
      <origin rpy="0 0 0" xyz="0 0 -0.0565"/>
      <geometry>
        <box size="0.022 0.025 0.04958"/>
      </geometry>
    </collision>
    <visual>
      <origin rpy="0 0 0" xyz="0 0 -0.04329"/>
      <geometry>
        <box size="0.022 0.025 0.04958"/>
      </geometry>
    </visual>
  </link>
  <gazebo reference="radius_1">
    <mu1>1000</mu1>
    <mu2>1000</mu2>
  </gazebo>
  <joint name="radius_1_joint" type="revolute">
    <parent link="humerus_1"/>
    <child link="radius_1"/>
    <origin rpy="0 0 0" xyz="0 0 -0.076"/>
    <axis xyz="0 1 0"/>
    <dynamics damping="0.1" friction="0.1"/>
    <limit effort="3.0" lower="-3.15" upper="3.15" velocity="0.5"/>
  </joint>
  <transmission name="radius_1_joint_transmission">
    <type>transmission_interface/SimpleTransmission</type>
    <joint name="radius_1_joint">
      <hardwareInterface>PositionJointInterface</hardwareInterface>
    </joint>
    <actuator name="radius_1_joint_motor">
      <mechanicalReduction>1</mechanicalReduction>
    </actuator>
  </transmission>
  <link name="radius_2">
    <inertial>
      <mass value="1"/>
      <inertia ixx="0.001" ixy="0.0" ixz="0.0" iyy="0.001" iyz="0.0" izz="0.001"/>
    </inertial>
    <collision>
      <origin rpy="0 0 0" xyz="0 0 -0.0565"/>
      <geometry>
        <box size="0.022 0.025 0.04958"/>
      </geometry>
    </collision>
    <visual>
      <origin rpy="0 0 0" xyz="0 0 -0.04329"/>
      <geometry>
        <box size="0.022 0.025 0.04958"/>
      </geometry>
    </visual>
  </link>
  <gazebo reference="radius_2">
    <mu1>1000</mu1>
    <mu2>1000</mu2>
  </gazebo>
  <joint name="radius_2_joint" type="revolute">
    <parent link="humerus_2"/>
    <child link="radius_2"/>
    <origin rpy="0 0 0" xyz="0 0 -0.076"/>
    <axis xyz="0 -1 0"/>
    <dynamics damping="0.1" friction="0.1"/>
    <limit effort="3.0" lower="-3.15" upper="3.15" velocity="0.5"/>
  </joint>
  <transmission name="radius_2_joint_transmission">
    <type>transmission_interface/SimpleTransmission</type>
    <joint name="radius_2_joint">
      <hardwareInterface>PositionJointInterface</hardwareInterface>
    </joint>
    <actuator name="radius_2_joint_motor">
      <mechanicalReduction>1</mechanicalReduction>
    </actuator>
  </transmission>
  <link name="tibula_2">
    <inertial>
      <mass value="1"/>
      <inertia ixx="0.001" ixy="0.0" ixz="0.0" iyy="0.001" iyz="0.0" izz="0.001"/>
    </inertial>
    <collision>
      <origin rpy="0 0 0" xyz="0 0 -0.04329"/>
      <geometry>
        <box size="0.022 0.025 0.04958"/>
      </geometry>
    </collision>
    <visual>
      <origin rpy="0 0 0" xyz="0 0 -0.04329"/>
      <geometry>
        <box size="0.022 0.025 0.04958"/>
      </geometry>
    </visual>
  </link>
  <gazebo reference="tibula_2">
    <mu1>1000</mu1>
    <mu2>1000</mu2>
  </gazebo>
  <joint name="tibula_2_joint" type="revolute">
    <parent link="femur_2"/>
    <child link="tibula_2"/>
    <origin rpy="0 0 0" xyz="0 0 -0.076"/>
    <axis xyz="0 -1 0"/>
    <dynamics damping="0.1" friction="0.1"/>
    <limit effort="3.0" lower="-3.15" upper="3.15" velocity="0.5"/>
  </joint>
  <transmission name="tibula_2_joint_transmission">
    <type>transmission_interface/SimpleTransmission</type>
    <joint name="tibula_2_joint">
      <hardwareInterface>PositionJointInterface</hardwareInterface>
    </joint>
    <actuator name="tibula_2_joint_motor">
      <mechanicalReduction>1</mechanicalReduction>
    </actuator>
  </transmission>
  <link name="tibula_1">
    <inertial>
      <mass value="1"/>
      <inertia ixx="0.001" ixy="0.0" ixz="0.0" iyy="0.001" iyz="0.0" izz="0.001"/>
    </inertial>
    <collision>
      <origin rpy="0 0 0" xyz="0 0 -0.04329"/>
      <geometry>
        <box size="0.022 0.025 0.04958"/>
      </geometry>
    </collision>
    <visual>
      <origin rpy="0 0 0" xyz="0 0 -0.04329"/>
      <geometry>
        <box size="0.022 0.025 0.04958"/>
      </geometry>
    </visual>
  </link>
  <gazebo reference="tibula_1">
    <mu1>1000</mu1>
    <mu2>1000</mu2>
  </gazebo>
  <joint name="tibula_1_joint" type="revolute">
    <parent link="femur_1"/>
    <child link="tibula_1"/>
    <origin rpy="0 0 0" xyz="0 0 -0.076"/>
    <axis xyz="0 1 0"/>
    <dynamics damping="0.1" friction="0.1"/>
    <limit effort="3.0" lower="-3.15" upper="3.15" velocity="0.5"/>
  </joint>
  <transmission name="tibula_1_joint_transmission">
    <type>transmission_interface/SimpleTransmission</type>
    <joint name="tibula_1_joint">
      <hardwareInterface>PositionJointInterface</hardwareInterface>
    </joint>
    <actuator name="tibula_1_joint_motor">
      <mechanicalReduction>1</mechanicalReduction>
    </actuator>
  </transmission>
  <gazebo>
    <plugin filename="libgazebo_ros_control.so" name="gazebo_ros_control">
      <robotParam>robot_description</robotParam>
    </plugin>
  </gazebo>
</robot>
