<sdf version='1.4'>
  <model name='ker'>
    <link name='body'>
      <pose>0 0 0 0 -0 0</pose>
      <inertial>
        <pose>0 0 -0.000408654 0 -0 0</pose>
        <mass>10.4</mass>
        <inertia>
          <ixx>0.00551969</ixx>
          <ixy>0</ixy>
          <ixz>-7.35e-06</ixz>
          <iyy>0.00600399</iyy>
          <iyz>-5.175e-06</iyz>
          <izz>0.0064365</izz>
        </inertia>
      </inertial>
      <collision name='body_collision'>
        <pose>0 0 0 0 -0 0</pose>
        <geometry>
          <mesh>
            <scale>1 1 1</scale>
            <uri>model://ker_description/meshes/start4_1.stl</uri>
          </mesh>
        </geometry>
      </collision>
      <collision name='body_collision_big_motor_1'>
        <pose>0.049 0.0345 -0.0095 0 -0 0</pose>
        <geometry>
          <box>
            <size>0.051 0.025 0.053</size>
          </box>
        </geometry>
      </collision>
      <collision name='body_collision_big_motor_2'>
        <pose>0.049 -0.0345 -0.011 0 -0 0</pose>
        <geometry>
          <box>
            <size>0.051 0.025 0.053</size>
          </box>
        </geometry>
      </collision>
      <collision name='body_collision_big_motor_3'>
        <pose>-0.049 -0.0345 -0.011 0 -0 0</pose>
        <geometry>
          <box>
            <size>0.051 0.025 0.053</size>
          </box>
        </geometry>
      </collision>
      <collision name='body_collision_big_motor_4'>
        <pose>-0.049 0.0345 -0.011 0 -0 0</pose>
        <geometry>
          <box>
            <size>0.051 0.025 0.053</size>
          </box>
        </geometry>
      </collision>
      <visual name='body_visual'>
        <pose>0 0 0 0 -0 0</pose>
        <geometry>
          <mesh>
            <scale>1 1 1</scale>
            <uri>model://ker_description/meshes/start4_1.stl</uri>
          </mesh>
        </geometry>
      </visual>
      <visual name='body_visual_big_motor_1'>
        <pose>0.049 0.0345 -0.0095 1.57075 -0 0</pose>
        <geometry>
          <box>
            <size>0.051 0.025 0.053</size>
          </box>
        </geometry>
      </visual>
      <visual name='body_visual_big_motor_2'>
        <pose>0.049 -0.0345 -0.011 1.57075 -0 0</pose>
        <geometry>
          <box>
            <size>0.051 0.025 0.053</size>
          </box>
        </geometry>
      </visual>
      <visual name='body_visual_big_motor_3'>
        <pose>-0.049 -0.0345 -0.011 1.57075 -0 0</pose>
        <geometry>
          <box>
            <size>0.051 0.025 0.053</size>
          </box>
        </geometry>
      </visual>
      <visual name='body_visual_big_motor_4'>
        <pose>-0.049 0.0345 -0.011 1.57075 -0 0</pose>
        <geometry>
          <box>
            <size>0.051 0.025 0.053</size>
          </box>
        </geometry>
      </visual>
      <velocity_decay>
        <linear>0</linear>
        <angular>0</angular>
      </velocity_decay>
    </link>
    <link name='motor_1'>
      <pose>0.0855 0.0345 -0.0095 0 -0 0</pose>
      <inertial>
        <pose>0 0 0 0 -0 0</pose>
        <mass>0.00167</mass>
        <inertia>
          <ixx>0.00208333</ixx>
          <ixy>0</ixy>
          <ixz>0</ixz>
          <iyy>0.00183333</iyy>
          <iyz>0</iyz>
          <izz>0.00183333</izz>
        </inertia>
      </inertial>
      <collision name='motor_1_collision'>
        <pose>0 0 0 0 -0 0</pose>
        <geometry>
          <box>
            <size>0.022 0.025 0.037</size>
          </box>
        </geometry>
      </collision>
      <visual name='motor_1_visual'>
        <pose>0 0 0 0 -0 0</pose>
        <geometry>
          <box>
            <size>0.022 0.025 0.037</size>
          </box>
        </geometry>
      </visual>
      <velocity_decay>
        <linear>0</linear>
        <angular>0</angular>
      </velocity_decay>
    </link>
    <joint name='motor_1_joint' type='revolute'>
      <child>motor_1</child>
      <parent>body</parent>
      <axis>
        <xyz>1 0 0</xyz>
        <limit>
          <lower>-3.15</lower>
          <upper>3.15</upper>
          <effort>3</effort>
          <velocity>0.5</velocity>
        </limit>
        <dynamics>
          <damping>0.1</damping>
        </dynamics>
      </axis>
    </joint>
    <link name='humerus_1'>
      <pose>0.0855 0.0345 -0.0095 0 -0 0</pose>
      <inertial>
        <pose>0 0 0 0 -0 0</pose>
        <mass>0.00167</mass>
        <inertia>
          <ixx>0.00208333</ixx>
          <ixy>0</ixy>
          <ixz>0</ixz>
          <iyy>0.00183333</iyy>
          <iyz>0</iyz>
          <izz>0.00183333</izz>
        </inertia>
      </inertial>
      <collision name='humerus_1_collision'>
        <pose>0 0 -0.0565 0 -0 0</pose>
        <geometry>
          <box>
            <size>0.022 0.025 0.076</size>
          </box>
        </geometry>
      </collision>
      <visual name='humerus_1_visual'>
        <pose>0 0 -0.0565 0 -0 0</pose>
        <geometry>
          <box>
            <size>0.022 0.025 0.076</size>
          </box>
        </geometry>
      </visual>
      <velocity_decay>
        <linear>0</linear>
        <angular>0</angular>
      </velocity_decay>
    </link>
    <joint name='humerus_1_joint' type='revolute'>
      <child>humerus_1</child>
      <parent>motor_1</parent>
      <axis>
        <xyz>0 1 0</xyz>
        <limit>
          <lower>-3.15</lower>
          <upper>3.15</upper>
          <effort>3</effort>
          <velocity>0.5</velocity>
        </limit>
        <dynamics>
          <damping>0.1</damping>
        </dynamics>
      </axis>
    </joint>
    <link name='radius_1'>
      <pose>0.0855 0.0345 -0.0855 0 -0 0</pose>
      <inertial>
        <pose>0 0 0 0 -0 0</pose>
        <mass>1</mass>
        <inertia>
          <ixx>0.001</ixx>
          <ixy>0</ixy>
          <ixz>0</ixz>
          <iyy>0.001</iyy>
          <iyz>0</iyz>
          <izz>0.001</izz>
        </inertia>
      </inertial>
      <collision name='radius_1_collision'>
        <pose>0 0 -0.0565 0 -0 0</pose>
        <geometry>
          <box>
            <size>0.022 0.025 0.04958</size>
          </box>
        </geometry>
        <surface>
          <contact>
            <ode/>
          </contact>
          <friction>
            <ode>
              <mu>1000</mu>
              <mu2>1000</mu2>
            </ode>
          </friction>
        </surface>
      </collision>
      <visual name='radius_1_visual'>
        <pose>0 0 -0.04329 0 -0 0</pose>
        <geometry>
          <box>
            <size>0.022 0.025 0.04958</size>
          </box>
        </geometry>
      </visual>
      <gravity>1</gravity>
      <velocity_decay>
        <linear>0</linear>
        <angular>0</angular>
      </velocity_decay>
      <self_collide>0</self_collide>
    </link>
    <joint name='radius_1_joint' type='revolute'>
      <child>radius_1</child>
      <parent>humerus_1</parent>
      <axis>
        <xyz>0 1 0</xyz>
        <limit>
          <lower>-3.15</lower>
          <upper>3.15</upper>
          <effort>3</effort>
          <velocity>0.5</velocity>
        </limit>
        <dynamics>
          <damping>0.1</damping>
        </dynamics>
      </axis>
    </joint>
    <link name='motor_2'>
      <pose>0.0855 -0.0345 -0.011 0 -0 0</pose>
      <inertial>
        <pose>0 0 0 0 -0 0</pose>
        <mass>0.00167</mass>
        <inertia>
          <ixx>0.00208333</ixx>
          <ixy>0</ixy>
          <ixz>0</ixz>
          <iyy>0.00183333</iyy>
          <iyz>0</iyz>
          <izz>0.00183333</izz>
        </inertia>
      </inertial>
      <collision name='motor_2_collision'>
        <pose>0 0 0 0 -0 0</pose>
        <geometry>
          <box>
            <size>0.022 0.025 0.037</size>
          </box>
        </geometry>
      </collision>
      <visual name='motor_2_visual'>
        <pose>0 0 0 0 -0 0</pose>
        <geometry>
          <box>
            <size>0.022 0.025 0.037</size>
          </box>
        </geometry>
      </visual>
      <velocity_decay>
        <linear>0</linear>
        <angular>0</angular>
      </velocity_decay>
    </link>
    <joint name='motor_2_joint' type='revolute'>
      <child>motor_2</child>
      <parent>body</parent>
      <axis>
        <xyz>1 0 0</xyz>
        <limit>
          <lower>-3.15</lower>
          <upper>3.15</upper>
          <effort>3</effort>
          <velocity>0.5</velocity>
        </limit>
        <dynamics>
          <damping>0.1</damping>
        </dynamics>
      </axis>
    </joint>
    <link name='humerus_2'>
      <pose>0.0855 -0.0345 -0.011 0 -0 0</pose>
      <inertial>
        <pose>0 0 0 0 -0 0</pose>
        <mass>0.00167</mass>
        <inertia>
          <ixx>0.00208333</ixx>
          <ixy>0</ixy>
          <ixz>0</ixz>
          <iyy>0.00183333</iyy>
          <iyz>0</iyz>
          <izz>0.00183333</izz>
        </inertia>
      </inertial>
      <collision name='humerus_2_collision'>
        <pose>0 0 -0.0565 0 -0 0</pose>
        <geometry>
          <box>
            <size>0.022 0.025 0.076</size>
          </box>
        </geometry>
      </collision>
      <visual name='humerus_2_visual'>
        <pose>0 0 -0.0565 0 -0 0</pose>
        <geometry>
          <box>
            <size>0.022 0.025 0.076</size>
          </box>
        </geometry>
      </visual>
      <velocity_decay>
        <linear>0</linear>
        <angular>0</angular>
      </velocity_decay>
    </link>
    <joint name='humerus_2_joint' type='revolute'>
      <child>humerus_2</child>
      <parent>motor_2</parent>
      <axis>
        <xyz>0 -1 0</xyz>
        <limit>
          <lower>-3.15</lower>
          <upper>3.15</upper>
          <effort>3</effort>
          <velocity>0.5</velocity>
        </limit>
        <dynamics>
          <damping>0.1</damping>
        </dynamics>
      </axis>
    </joint>
    <link name='radius_2'>
      <pose>0.0855 -0.0345 -0.087 0 -0 0</pose>
      <inertial>
        <pose>0 0 0 0 -0 0</pose>
        <mass>1</mass>
        <inertia>
          <ixx>0.001</ixx>
          <ixy>0</ixy>
          <ixz>0</ixz>
          <iyy>0.001</iyy>
          <iyz>0</iyz>
          <izz>0.001</izz>
        </inertia>
      </inertial>
      <collision name='radius_2_collision'>
        <pose>0 0 -0.0565 0 -0 0</pose>
        <geometry>
          <box>
            <size>0.022 0.025 0.04958</size>
          </box>
        </geometry>
        <surface>
          <contact>
            <ode/>
          </contact>
          <friction>
            <ode>
              <mu>1000</mu>
              <mu2>1000</mu2>
            </ode>
          </friction>
        </surface>
      </collision>
      <visual name='radius_2_visual'>
        <pose>0 0 -0.04329 0 -0 0</pose>
        <geometry>
          <box>
            <size>0.022 0.025 0.04958</size>
          </box>
        </geometry>
      </visual>
      <gravity>1</gravity>
      <velocity_decay>
        <linear>0</linear>
        <angular>0</angular>
      </velocity_decay>
      <self_collide>0</self_collide>
    </link>
    <joint name='radius_2_joint' type='revolute'>
      <child>radius_2</child>
      <parent>humerus_2</parent>
      <axis>
        <xyz>0 -1 0</xyz>
        <limit>
          <lower>-3.15</lower>
          <upper>3.15</upper>
          <effort>3</effort>
          <velocity>0.5</velocity>
        </limit>
        <dynamics>
          <damping>0.1</damping>
        </dynamics>
      </axis>
    </joint>
    <link name='motor_3'>
      <pose>-0.0125 -0.0345 -0.011 0 -0 0</pose>
      <inertial>
        <pose>0 0 0 0 -0 0</pose>
        <mass>0.00167</mass>
        <inertia>
          <ixx>0.00208333</ixx>
          <ixy>0</ixy>
          <ixz>0</ixz>
          <iyy>0.00183333</iyy>
          <iyz>0</iyz>
          <izz>0.00183333</izz>
        </inertia>
      </inertial>
      <collision name='motor_3_collision'>
        <pose>0 0 0 0 -0 0</pose>
        <geometry>
          <box>
            <size>0.022 0.025 0.037</size>
          </box>
        </geometry>
      </collision>
      <visual name='motor_3_visual'>
        <pose>0 0 0 0 -0 0</pose>
        <geometry>
          <box>
            <size>0.022 0.025 0.037</size>
          </box>
        </geometry>
      </visual>
      <velocity_decay>
        <linear>0</linear>
        <angular>0</angular>
      </velocity_decay>
    </link>
    <joint name='motor_3_joint' type='revolute'>
      <child>motor_3</child>
      <parent>body</parent>
      <axis>
        <xyz>1 0 0</xyz>
        <limit>
          <lower>-3.15</lower>
          <upper>3.15</upper>
          <effort>3</effort>
          <velocity>0.5</velocity>
        </limit>
        <dynamics>
          <damping>0.1</damping>
        </dynamics>
      </axis>
    </joint>
    <link name='femur_2'>
      <pose>-0.0125 -0.0345 -0.011 0 -0 0</pose>
      <inertial>
        <pose>0 0 0 0 -0 0</pose>
        <mass>0.00167</mass>
        <inertia>
          <ixx>0.00208333</ixx>
          <ixy>0</ixy>
          <ixz>0</ixz>
          <iyy>0.00183333</iyy>
          <iyz>0</iyz>
          <izz>0.00183333</izz>
        </inertia>
      </inertial>
      <collision name='femur_2_collision'>
        <pose>0 0 -0.0565 0 -0 0</pose>
        <geometry>
          <box>
            <size>0.022 0.025 0.076</size>
          </box>
        </geometry>
      </collision>
      <visual name='femur_2_visual'>
        <pose>0 0 -0.0565 0 -0 0</pose>
        <geometry>
          <box>
            <size>0.022 0.025 0.076</size>
          </box>
        </geometry>
      </visual>
      <velocity_decay>
        <linear>0</linear>
        <angular>0</angular>
      </velocity_decay>
    </link>
    <joint name='femur_2_joint' type='revolute'>
      <child>femur_2</child>
      <parent>motor_3</parent>
      <axis>
        <xyz>0 -1 0</xyz>
        <limit>
          <lower>-3.15</lower>
          <upper>3.15</upper>
          <effort>3</effort>
          <velocity>0.5</velocity>
        </limit>
        <dynamics>
          <damping>0.1</damping>
        </dynamics>
      </axis>
    </joint>
    <link name='tibula_2'>
      <pose>-0.0125 -0.0345 -0.087 0 -0 0</pose>
      <inertial>
        <pose>0 0 0 0 -0 0</pose>
        <mass>1</mass>
        <inertia>
          <ixx>0.001</ixx>
          <ixy>0</ixy>
          <ixz>0</ixz>
          <iyy>0.001</iyy>
          <iyz>0</iyz>
          <izz>0.001</izz>
        </inertia>
      </inertial>
      <collision name='tibula_2_collision'>
        <pose>0 0 -0.04329 0 -0 0</pose>
        <geometry>
          <box>
            <size>0.022 0.025 0.04958</size>
          </box>
        </geometry>
        <surface>
          <contact>
            <ode/>
          </contact>
          <friction>
            <ode>
              <mu>1000</mu>
              <mu2>1000</mu2>
            </ode>
          </friction>
        </surface>
      </collision>
      <visual name='tibula_2_visual'>
        <pose>0 0 -0.04329 0 -0 0</pose>
        <geometry>
          <box>
            <size>0.022 0.025 0.04958</size>
          </box>
        </geometry>
      </visual>
      <gravity>1</gravity>
      <velocity_decay>
        <linear>0</linear>
        <angular>0</angular>
      </velocity_decay>
      <self_collide>0</self_collide>
    </link>
    <joint name='tibula_2_joint' type='revolute'>
      <child>tibula_2</child>
      <parent>femur_2</parent>
      <axis>
        <xyz>0 -1 0</xyz>
        <limit>
          <lower>-3.15</lower>
          <upper>3.15</upper>
          <effort>3</effort>
          <velocity>0.5</velocity>
        </limit>
        <dynamics>
          <damping>0.1</damping>
        </dynamics>
      </axis>
    </joint>
    <link name='motor_4'>
      <pose>-0.0125 0.0345 -0.011 0 -0 0</pose>
      <inertial>
        <pose>0 0 0 0 -0 0</pose>
        <mass>0.00167</mass>
        <inertia>
          <ixx>0.00208333</ixx>
          <ixy>0</ixy>
          <ixz>0</ixz>
          <iyy>0.00183333</iyy>
          <iyz>0</iyz>
          <izz>0.00183333</izz>
        </inertia>
      </inertial>
      <collision name='motor_4_collision'>
        <pose>0 0 0 0 -0 0</pose>
        <geometry>
          <box>
            <size>0.022 0.025 0.037</size>
          </box>
        </geometry>
      </collision>
      <visual name='motor_4_visual'>
        <pose>0 0 0 0 -0 0</pose>
        <geometry>
          <box>
            <size>0.022 0.025 0.037</size>
          </box>
        </geometry>
      </visual>
      <velocity_decay>
        <linear>0</linear>
        <angular>0</angular>
      </velocity_decay>
    </link>
    <joint name='motor_4_joint' type='revolute'>
      <child>motor_4</child>
      <parent>body</parent>
      <axis>
        <xyz>1 0 0</xyz>
        <limit>
          <lower>-3.15</lower>
          <upper>3.15</upper>
          <effort>3</effort>
          <velocity>0.5</velocity>
        </limit>
        <dynamics>
          <damping>0.1</damping>
        </dynamics>
      </axis>
    </joint>
    <link name='femur_1'>
      <pose>-0.0125 0.0345 -0.011 0 -0 0</pose>
      <inertial>
        <pose>0 0 0 0 -0 0</pose>
        <mass>0.00167</mass>
        <inertia>
          <ixx>0.00208333</ixx>
          <ixy>0</ixy>
          <ixz>0</ixz>
          <iyy>0.00183333</iyy>
          <iyz>0</iyz>
          <izz>0.00183333</izz>
        </inertia>
      </inertial>
      <collision name='femur_1_collision'>
        <pose>0 0 -0.0565 0 -0 0</pose>
        <geometry>
          <box>
            <size>0.022 0.025 0.076</size>
          </box>
        </geometry>
      </collision>
      <visual name='femur_1_visual'>
        <pose>0 0 -0.0565 0 -0 0</pose>
        <geometry>
          <box>
            <size>0.022 0.025 0.076</size>
          </box>
        </geometry>
      </visual>
      <velocity_decay>
        <linear>0</linear>
        <angular>0</angular>
      </velocity_decay>
    </link>
    <joint name='femur_1_joint' type='revolute'>
      <child>femur_1</child>
      <parent>motor_4</parent>
      <axis>
        <xyz>0 1 0</xyz>
        <limit>
          <lower>-3.15</lower>
          <upper>3.15</upper>
          <effort>3</effort>
          <velocity>0.5</velocity>
        </limit>
        <dynamics>
          <damping>0.1</damping>
        </dynamics>
      </axis>
    </joint>
    <link name='tibula_1'>
      <pose>-0.0125 0.0345 -0.087 0 -0 0</pose>
      <inertial>
        <pose>0 0 0 0 -0 0</pose>
        <mass>1</mass>
        <inertia>
          <ixx>0.001</ixx>
          <ixy>0</ixy>
          <ixz>0</ixz>
          <iyy>0.001</iyy>
          <iyz>0</iyz>
          <izz>0.001</izz>
        </inertia>
      </inertial>
      <collision name='tibula_1_collision'>
        <pose>0 0 -0.04329 0 -0 0</pose>
        <geometry>
          <box>
            <size>0.022 0.025 0.04958</size>
          </box>
        </geometry>
        <surface>
          <contact>
            <ode/>
          </contact>
          <friction>
            <ode>
              <mu>1000</mu>
              <mu2>1000</mu2>
            </ode>
          </friction>
        </surface>
      </collision>
      <visual name='tibula_1_visual'>
        <pose>0 0 -0.04329 0 -0 0</pose>
        <geometry>
          <box>
            <size>0.022 0.025 0.04958</size>
          </box>
        </geometry>
      </visual>
      <gravity>1</gravity>
      <velocity_decay>
        <linear>0</linear>
        <angular>0</angular>
      </velocity_decay>
      <self_collide>0</self_collide>
    </link>
    <joint name='tibula_1_joint' type='revolute'>
      <child>tibula_1</child>
      <parent>femur_1</parent>
      <axis>
        <xyz>0 1 0</xyz>
        <limit>
          <lower>-3.15</lower>
          <upper>3.15</upper>
          <effort>3</effort>
          <velocity>0.5</velocity>
        </limit>
        <dynamics>
          <damping>0.1</damping>
        </dynamics>
      </axis>
    </joint>
    <static>0</static>
    <plugin name='gazebo_ros_control' filename='libgazebo_ros_control.so'>
      <robotParam>robot_description</robotParam>
    </plugin>
  </model>
</sdf>
